<?xml version="1.0" encoding="utf-8"?>
<!-- This URDF was automatically created by SolidWorks to URDF Exporter! Originally created by Stephen Brawner (brawner@gmail.com) 
     Commit Version: 1.6.0-4-g7f85cfe  Build Version: 1.6.7995.38578
     For more information, please see http://wiki.ros.org/sw_urdf_exporter -->
<robot
  name="mecanum">
  <link
    name="base_link">
    <inertial>
      <origin
        xyz="-0.0857489441407666 0.120087688066747 0.0626062346225724"
        rpy="0 0 0" />
      <mass
        value="2.85737754623623" />
      <inertia
        ixx="0.00434208299750416"
        ixy="-7.26803903582791E-07"
        ixz="3.47982147594385E-06"
        iyy="0.00236576255288547"
        iyz="0.000157655614701444"
        izz="0.00606172623265242" />
    </inertial>
    <visual>
      <origin
        xyz="0 0 0"
        rpy="0 0 0" />
      <geometry>
        <mesh
          filename="package://mecanum/meshes/base_link.STL" />
      </geometry>
      <material
        name="">
        <color
          rgba="0.792156862745098 0.819607843137255 0.933333333333333 1" />
      </material>
    </visual>
    <collision>
      <origin
        xyz="0 0 0"
        rpy="0 0 0" />
      <geometry>
        <mesh
          filename="package://mecanum/meshes/base_link.STL" />
      </geometry>
    </collision>
  </link>
  <link
    name="Left_Forward">
    <inertial>
      <origin
        xyz="0 0.014403 0"
        rpy="0 0 0" />
      <mass
        value="0.18499" />
      <inertia
        ixx="0.00010038"
        ixy="-1.3994E-20"
        ixz="-4.1158E-21"
        iyy="0.00015649"
        iyz="-6.2685E-21"
        izz="0.00010038" />
    </inertial>
    <visual>
      <origin
        xyz="0 0 0"
        rpy="0 0 0" />
      <geometry>
        <mesh
          filename="package://mecanum/meshes/Left_Forward.STL" />
      </geometry>
      <material
        name="">
        <color
          rgba="1 1 0 1" />
      </material>
    </visual>
    <collision>
      <origin
        xyz="0 0 0"
        rpy="0 0 0" />
      <geometry>
        <mesh
          filename="package://mecanum/meshes/Left_Forward.STL" />
      </geometry>
    </collision>
  </link>
  <joint
    name="leftforwardjoint"
    type="continuous">
    <origin
      xyz="-0.16056 -0.061135 -0.020707"
      rpy="0 0 0" />
    <parent
      link="base_link" />
    <child
      link="Left_Forward" />
    <axis
      xyz="0 -1 0" />
    <limit
      effort="10"
      velocity="10" />
    <dynamics
      damping="0.1"
      friction="0.1" />
  </joint>
  <link
    name="left_backward">
    <inertial>
      <origin
        xyz="0 0.014403 0"
        rpy="0 0 0" />
      <mass
        value="0.18499" />
      <inertia
        ixx="0.00010038"
        ixy="-1.1482E-20"
        ixz="8.3384E-21"
        iyy="0.00015649"
        iyz="7.4768E-21"
        izz="0.00010038" />
    </inertial>
    <visual>
      <origin
        xyz="0 0 0"
        rpy="0 0 0" />
      <geometry>
        <mesh
          filename="package://mecanum/meshes/left_backward.STL" />
      </geometry>
      <material
        name="">
        <color
          rgba="1 1 0 1" />
      </material>
    </visual>
    <collision>
      <origin
        xyz="0 0 0"
        rpy="0 0 0" />
      <geometry>
        <mesh
          filename="package://mecanum/meshes/left_backward.STL" />
      </geometry>
    </collision>
  </link>
  <joint
    name="leftbackwardsjoint"
    type="continuous">
    <origin
      xyz="-0.0095629 -0.062959 -0.021396"
      rpy="0 0 0" />
    <parent
      link="base_link" />
    <child
      link="left_backward" />
    <axis
      xyz="0 -1 0" />
    <limit
      effort="10"
      velocity="10" />
    <dynamics
      damping="0.1"
      friction="0.1" />
  </joint>
  <link
    name="Right_foward">
    <inertial>
      <origin
        xyz="2.7756E-17 -0.014403 0"
        rpy="0 0 0" />
      <mass
        value="0.18499" />
      <inertia
        ixx="0.00010038"
        ixy="-2.195E-21"
        ixz="-8.1573E-22"
        iyy="0.00015649"
        iyz="-2.6959E-21"
        izz="0.00010038" />
    </inertial>
    <visual>
      <origin
        xyz="0 0 0"
        rpy="0 0 0" />
      <geometry>
        <mesh
          filename="package://mecanum/meshes/Right_foward.STL" />
      </geometry>
      <material
        name="">
        <color
          rgba="1 1 0 1" />
      </material>
    </visual>
    <collision>
      <origin
        xyz="0 0 0"
        rpy="0 0 0" />
      <geometry>
        <mesh
          filename="package://mecanum/meshes/Right_foward.STL" />
      </geometry>
    </collision>
  </link>
  <joint
    name="rightforwardjoint"
    type="continuous">
    <origin
      xyz="-0.16048 0.30265 -0.021346"
      rpy="0 0 0" />
    <parent
      link="base_link" />
    <child
      link="Right_foward" />
    <axis
      xyz="0 1 0" />
    <limit
      effort="10"
      velocity="10" />
    <dynamics
      damping="0.1"
      friction="0.1" />
  </joint>
  <link
    name="Right_backwards">
    <inertial>
      <origin
        xyz="0 -0.014403 -6.9389E-18"
        rpy="0 0 0" />
      <mass
        value="0.18499" />
      <inertia
        ixx="0.00010038"
        ixy="-1.3174E-20"
        ixz="3.4462E-21"
        iyy="0.00015649"
        iyz="5.8186E-21"
        izz="0.00010038" />
    </inertial>
    <visual>
      <origin
        xyz="0 0 0"
        rpy="0 0 0" />
      <geometry>
        <mesh
          filename="package://mecanum/meshes/Right_backwards.STL" />
      </geometry>
      <material
        name="">
        <color
          rgba="1 1 0 1" />
      </material>
    </visual>
    <collision>
      <origin
        xyz="0 0 0"
        rpy="0 0 0" />
      <geometry>
        <mesh
          filename="package://mecanum/meshes/Right_backwards.STL" />
      </geometry>
    </collision>
  </link>
  <joint
    name="rightbackwardsjoint"
    type="continuous">
    <origin
      xyz="-0.010241 0.30265 -0.021154"
      rpy="0 0 0" />
    <parent
      link="base_link" />
    <child
      link="Right_backwards" />
    <axis
      xyz="0 1 0" />
    <limit
      effort="10"
      velocity="10" />
    <dynamics
      damping="0.1"
      friction="0.1" />
  </joint>
</robot>